{"uuid": "40c88c70-3c33-4a2c-97ad-9cdfdbcf44e7", "children": ["a1e2f289-1313-4459-a134-f81cb1eccb99"], "befores": [{"name": "xunit_setup_class_fixture_Test_Loginfail", "status": "broken", "statusDetails": {"message": "selenium.common.exceptions.WebDriverException: Message: unknown error: cannot connect to chrome at 127.0.0.1:9222\nfrom chrome not reachable\n\n", "trace": "  File \"/Library/Frameworks/Python.framework/Versions/3.9/lib/python3.9/site-packages/pluggy/callers.py\", line 187, in _multicall\n    res = hook_impl.function(*args)\n  File \"/Library/Frameworks/Python.framework/Versions/3.9/lib/python3.9/site-packages/_pytest/fixtures.py\", line 1126, in pytest_fixture_setup\n    result = call_fixture_func(fixturefunc, request, kwargs)\n  File \"/Library/Frameworks/Python.framework/Versions/3.9/lib/python3.9/site-packages/_pytest/fixtures.py\", line 925, in call_fixture_func\n    fixture_result = next(generator)\n  File \"/Library/Frameworks/Python.framework/Versions/3.9/lib/python3.9/site-packages/_pytest/python.py\", line 811, in xunit_setup_class_fixture\n    _call_with_optional_argument(func, self.obj)\n  File \"/Library/Frameworks/Python.framework/Versions/3.9/lib/python3.9/site-packages/_pytest/python.py\", line 739, in _call_with_optional_argument\n    func(arg)\n  File \"/Users/liuyue/Desktop/workspace/cases/test_loginfail.py\", line 20, in setup_class\n    self.web.openbrowser()\n  File \"/Users/liuyue/Desktop/workspace/common/initialization.py\", line 27, in openbrowser\n    self.driver = webdriver.Chrome(options=option)\n  File \"/Library/Frameworks/Python.framework/Versions/3.9/lib/python3.9/site-packages/selenium/webdriver/chrome/webdriver.py\", line 76, in __init__\n    RemoteWebDriver.__init__(\n  File \"/Library/Frameworks/Python.framework/Versions/3.9/lib/python3.9/site-packages/selenium/webdriver/remote/webdriver.py\", line 157, in __init__\n    self.start_session(capabilities, browser_profile)\n  File \"/Library/Frameworks/Python.framework/Versions/3.9/lib/python3.9/site-packages/selenium/webdriver/remote/webdriver.py\", line 252, in start_session\n    response = self.execute(Command.NEW_SESSION, parameters)\n  File \"/Library/Frameworks/Python.framework/Versions/3.9/lib/python3.9/site-packages/selenium/webdriver/remote/webdriver.py\", line 321, in execute\n    self.error_handler.check_response(response)\n  File \"/Library/Frameworks/Python.framework/Versions/3.9/lib/python3.9/site-packages/selenium/webdriver/remote/errorhandler.py\", line 242, in check_response\n    raise exception_class(message, screen, stacktrace)\n"}, "start": 1622215945841, "stop": 1622216006910}], "start": 1622215945841, "stop": 1622216007030}